<?xml version="1.0"?>
<robot name="igvc_robot">

  <!-- Link 1: Chassis (Body of the car) -->
  <link name="chassis">
    <inertial>
      <mass value="10.0" />
      <inertia ixx="0.1" ixy="0.0" ixz="0.0" iyy="0.1" iyz="0.0" izz="0.1" />
    </inertial>
    <visual>
      <geometry>
        <box size="0.6 0.3 0.2"/>
      </geometry>
      <material name="green"/>
    </visual>
    <collision>
      <geometry>
        <box size="0.6 0.3 0.2"/>
      </geometry>
    </collision>
  </link>

  <!-- Link 2: Front Left Wheel -->
  <link name="front_left_wheel">
    <inertial>
      <mass value="0.5" />
      <inertia ixx="0.001" ixy="0.0" ixz="0.0" iyy="0.001" iyz="0.0" izz="0.001" />
    </inertial>
    <visual>
      <geometry>
        <cylinder radius="0.1" length="0.05"/>
      </geometry>
      <material name="black"/>
    </visual>
    <collision>
      <geometry>
        <cylinder radius="0.1" length="0.05"/>
      </geometry>
    </collision>
  </link>

  <!-- Link 3: Front Right Wheel -->
  <link name="front_right_wheel">
    <inertial>
      <mass value="0.5" />
      <inertia ixx="0.001" ixy="0.0" ixz="0.0" iyy="0.001" iyz="0.0" izz="0.001" />
    </inertial>
    <visual>
      <geometry>
        <cylinder radius="0.1" length="0.05"/>
      </geometry>
      <material name="black"/>
    </visual>
    <collision>
      <geometry>
        <cylinder radius="0.1" length="0.05"/>
      </geometry>
    </collision>
  </link>

  <!-- Link 4: Rear Left Wheel -->
  <link name="rear_left_wheel">
    <inertial>
      <mass value="0.5" />
      <inertia ixx="0.001" ixy="0.0" ixz="0.0" iyy="0.001" iyz="0.0" izz="0.001" />
    </inertial>
    <visual>
      <geometry>
        <cylinder radius="0.1" length="0.05"/>
      </geometry>
      <material name="black"/>
    </visual>
    <collision>
      <geometry>
        <cylinder radius="0.1" length="0.05"/>
      </geometry>
    </collision>
  </link>

  <!-- Link 5: Rear Right Wheel -->
  <link name="rear_right_wheel">
    <inertial>
      <mass value="0.5" />
      <inertia ixx="0.001" ixy="0.0" ixz="0.0" iyy="0.001" iyz="0.0" izz="0.001" />
    </inertial>
    <visual>
      <geometry>
        <cylinder radius="0.1" length="0.05"/>
      </geometry>
      <material name="black"/>
    </visual>
    <collision>
      <geometry>
        <cylinder radius="0.1" length="0.05"/>
      </geometry>
    </collision>
  </link>

  <!-- Joint 1: Front Left Wheel Joint -->
  <joint name="front_left_wheel_joint" type="revolute">
    <parent link="chassis"/>
    <child link="front_left_wheel"/>
    <origin xyz="0.25 0.15 0.1" rpy="0 0 0"/>
    <axis xyz="0 0 1"/>
    <limit lower="-1.57" upper="1.57" effort="100" velocity="10"/>
  </joint>

  <!-- Joint 2: Front Right Wheel Joint -->
  <joint name="front_right_wheel_joint" type="revolute">
    <parent link="chassis"/>
    <child link="front_right_wheel"/>
    <origin xyz="0.25 -0.15 0.1" rpy="0 0 0"/>
    <axis xyz="0 0 1"/>
    <limit lower="-1.57" upper="1.57" effort="100" velocity="10"/>
  </joint>

  <!-- Joint 3: Rear Left Wheel Joint -->
  <joint name="rear_left_wheel_joint" type="revolute">
    <parent link="chassis"/>
    <child link="rear_left_wheel"/>
    <origin xyz="-0.25 0.15 0.1" rpy="0 0 0"/>
    <axis xyz="0 0 1"/>
    <limit lower="-1.57" upper="1.57" effort="100" velocity="10"/>
  </joint>

  <!-- Joint 4: Rear Right Wheel Joint -->
  <joint name="rear_right_wheel_joint" type="revolute">
    <parent link="chassis"/>
    <child link="rear_right_wheel"/>
    <origin xyz="-0.25 -0.15 0.1" rpy="0 0 0"/>
    <axis xyz="0 0 1"/>
    <limit lower="-1.57" upper="1.57" effort="100" velocity="10"/>
  </joint>

</robot>



