<?xml version="1.0"?>
<robot name="rolling_chassis">

  <!-- Define grey material -->
  <material name="grey">
    <color rgba="0.5 0.5 0.5 1"/> <!-- 50% grey -->
  </material>

  <!-- Base Link -->
  <link name="base_link">
    <visual>
      <geometry>
        <box size="0.4064 0.9652 0.3556"/> <!-- 16in x 38in x 14in in meters -->
      </geometry>
      <origin xyz="0 0 0.1778" rpy="0 0 0"/>
      <material name="grey"/>
    </visual>
    <collision>
      <geometry>
        <box size="0.4064 0.9652 0.3556"/>
      </geometry>
      <origin xyz="0 0 0.1778" rpy="0 0 0"/>
    </collision>
  </link>

  <!-- Left Wheel -->
  <link name="left_wheel"/>
  <joint name="left_wheel_joint" type="continuous">
    <parent link="base_link"/>
    <child link="left_wheel"/>
    <origin xyz="0 0.2032 0" rpy="0 0 0"/>
    <axis xyz="0 1 0"/>
  </joint>

  <!-- Right Wheel -->
  <link name="right_wheel"/>
  <joint name="right_wheel_joint" type="continuous">
    <parent link="base_link"/>
    <child link="right_wheel"/>
    <origin xyz="0 -0.2032 0" rpy="0 0 0"/>
    <axis xyz="0 1 0"/>
  </joint>

  <!-- Caster Swivel Joint -->
  <link name="caster_swivel"/>
  <joint name="caster_swivel_joint" type="revolute">
    <parent link="base_link"/>
    <child link="caster_swivel"/>
    <origin xyz="-0.3048 0 0" rpy="0 0 0"/>
    <axis xyz="0 0 1"/>
    <limit lower="-3.14" upper="3.14" effort="0.1" velocity="1.0"/>
  </joint>

  <!-- Caster Wheel -->
  <link name="caster_wheel"/>
  <joint name="caster_wheel_spin" type="continuous">
    <parent link="caster_swivel"/>
    <child link="caster_wheel"/>
    <origin xyz="0 -0.08202 -0.0508" rpy="0 0 0"/> <!-- Offset down and back a bit -->
    <axis xyz="0 1 0"/>
  </joint>
  
  <!-- Camera Mount -->
  <link name="camera_mount"/>
  <joint name="camera_mount_joint" type="fixed">
    <parent link="base_link"/>
    <child link="camera_mount"/>
    <origin xyz="0 0 0.4556" rpy="0 0 0"/> <!-- 14in + 0.1m -->
  </joint>
  <visual>
    <geometry>
      <box size="0.05 0.05 0.05"/>
    </geometry>
    <origin xyz="0 0 0" rpy="0 0 0"/>
    <material name="blue"/>
  </visual>

  <!-- LiDAR Mount -->
  <link name="lidar_mount"/>
  <joint name="lidar_mount_joint" type="fixed">
    <parent link="base_link"/>
    <child link="lidar_mount"/>
    <origin xyz="0 0 0.4756" rpy="0 0 0"/> <!-- 14in + 0.12m -->
  </joint>
  <visual>
    <geometry>
      <cylinder radius="0.05" length="0.05"/>
    </geometry>
    <origin xyz="0 0 0" rpy="0 0 0"/>
    <material name="red"/>
  </visual>

</robot>


